Traceback (most recent call last):
  File "D:\Program Files\Python39\lib\site-packages\jupyter_cache\executors\utils.py", line 58, in single_nb_execution
    executenb(
  File "D:\Program Files\Python39\lib\site-packages\nbclient\client.py", line 1314, in execute
    return NotebookClient(nb=nb, resources=resources, km=km, **kwargs).execute()
  File "D:\Program Files\Python39\lib\site-packages\jupyter_core\utils\__init__.py", line 165, in wrapped
    return loop.run_until_complete(inner)
  File "D:\Program Files\Python39\lib\asyncio\base_events.py", line 642, in run_until_complete
    return future.result()
  File "D:\Program Files\Python39\lib\site-packages\nbclient\client.py", line 709, in async_execute
    await self.async_execute_cell(
  File "D:\Program Files\Python39\lib\site-packages\nbclient\client.py", line 1062, in async_execute_cell
    await self._check_raise_for_error(cell, cell_index, exec_reply)
  File "D:\Program Files\Python39\lib\site-packages\nbclient\client.py", line 918, in _check_raise_for_error
    raise CellExecutionError.from_cell_and_msg(cell, exec_reply_content)
nbclient.exceptions.CellExecutionError: An error occurred while executing the following cell:
------------------
import os
import random
import numpy as np
import shutil

print(len(os.listdir('annotations')))
print(len(os.listdir('images')))

!mkdir test_images
!mkdir test_annotations


random.seed(1234)
idx = random.sample(range(853), 170)

for img in np.array(sorted(os.listdir('images')))[idx]:
    shutil.move('images/'+img, 'test_images/'+img)

for annot in np.array(sorted(os.listdir('annotations')))[idx]:
    shutil.move('annotations/'+annot, 'test_annotations/'+annot)

print(len(os.listdir('annotations')))
print(len(os.listdir('images')))
print(len(os.listdir('test_annotations')))
print(len(os.listdir('test_images')))
------------------


[1;31m---------------------------------------------------------------------------[0m
[1;31mFileNotFoundError[0m                         Traceback (most recent call last)
Cell [1;32mIn[3], line 6[0m
[0;32m      3[0m [38;5;28;01mimport[39;00m [38;5;21;01mnumpy[39;00m [38;5;28;01mas[39;00m [38;5;21;01mnp[39;00m
[0;32m      4[0m [38;5;28;01mimport[39;00m [38;5;21;01mshutil[39;00m
[1;32m----> 6[0m [38;5;28mprint[39m([38;5;28mlen[39m([43mos[49m[38;5;241;43m.[39;49m[43mlistdir[49m[43m([49m[38;5;124;43m'[39;49m[38;5;124;43mannotations[39;49m[38;5;124;43m'[39;49m[43m)[49m))
[0;32m      7[0m [38;5;28mprint[39m([38;5;28mlen[39m(os[38;5;241m.[39mlistdir([38;5;124m'[39m[38;5;124mimages[39m[38;5;124m'[39m)))
[0;32m      9[0m get_ipython()[38;5;241m.[39msystem([38;5;124m'[39m[38;5;124mmkdir test_images[39m[38;5;124m'[39m)

[1;31mFileNotFoundError[0m: [WinError 3] 系统找不到指定的路径。: 'annotations'

