Traceback (most recent call last):
  File "D:\Program Files\Python39\lib\site-packages\jupyter_cache\executors\utils.py", line 58, in single_nb_execution
    executenb(
  File "D:\Program Files\Python39\lib\site-packages\nbclient\client.py", line 1314, in execute
    return NotebookClient(nb=nb, resources=resources, km=km, **kwargs).execute()
  File "D:\Program Files\Python39\lib\site-packages\jupyter_core\utils\__init__.py", line 165, in wrapped
    return loop.run_until_complete(inner)
  File "D:\Program Files\Python39\lib\asyncio\base_events.py", line 642, in run_until_complete
    return future.result()
  File "D:\Program Files\Python39\lib\site-packages\nbclient\client.py", line 709, in async_execute
    await self.async_execute_cell(
  File "D:\Program Files\Python39\lib\site-packages\nbclient\client.py", line 1062, in async_execute_cell
    await self._check_raise_for_error(cell, cell_index, exec_reply)
  File "D:\Program Files\Python39\lib\site-packages\nbclient\client.py", line 918, in _check_raise_for_error
    raise CellExecutionError.from_cell_and_msg(cell, exec_reply_content)
nbclient.exceptions.CellExecutionError: An error occurred while executing the following cell:
------------------
# Pip install method (recommended)

!pip install "ultralytics<=8.3.40"

from IPython import display
display.clear_output()

import ultralytics
ultralytics.checks()
------------------


[1;31m---------------------------------------------------------------------------[0m
[1;31mModuleNotFoundError[0m                       Traceback (most recent call last)
Cell [1;32mIn[5], line 8[0m
[0;32m      5[0m [38;5;28;01mfrom[39;00m [38;5;21;01mIPython[39;00m [38;5;28;01mimport[39;00m display
[0;32m      6[0m display[38;5;241m.[39mclear_output()
[1;32m----> 8[0m [38;5;28;01mimport[39;00m [38;5;21;01multralytics[39;00m
[0;32m      9[0m ultralytics[38;5;241m.[39mchecks()

[1;31mModuleNotFoundError[0m: No module named 'ultralytics'

