Traceback (most recent call last):
  File "D:\Program Files\Python39\lib\site-packages\jupyter_cache\executors\utils.py", line 58, in single_nb_execution
    executenb(
  File "D:\Program Files\Python39\lib\site-packages\nbclient\client.py", line 1314, in execute
    return NotebookClient(nb=nb, resources=resources, km=km, **kwargs).execute()
  File "D:\Program Files\Python39\lib\site-packages\jupyter_core\utils\__init__.py", line 165, in wrapped
    return loop.run_until_complete(inner)
  File "D:\Program Files\Python39\lib\asyncio\base_events.py", line 642, in run_until_complete
    return future.result()
  File "D:\Program Files\Python39\lib\site-packages\nbclient\client.py", line 709, in async_execute
    await self.async_execute_cell(
  File "D:\Program Files\Python39\lib\site-packages\nbclient\client.py", line 1062, in async_execute_cell
    await self._check_raise_for_error(cell, cell_index, exec_reply)
  File "D:\Program Files\Python39\lib\site-packages\nbclient\client.py", line 918, in _check_raise_for_error
    raise CellExecutionError.from_cell_and_msg(cell, exec_reply_content)
nbclient.exceptions.CellExecutionError: An error occurred while executing the following cell:
------------------
train_loader  = DataLoader(
    VictorianDataset(root, color_transforms_=color_transforms_, gray_transforms_=gray_transforms_),
    batch_size=batch_size,
    shuffle=True
)
------------------


[1;31m---------------------------------------------------------------------------[0m
[1;31mValueError[0m                                Traceback (most recent call last)
Cell [1;32mIn[6], line 1[0m
[1;32m----> 1[0m train_loader  [38;5;241m=[39m [43mDataLoader[49m[43m([49m
[0;32m      2[0m [43m    [49m[43mVictorianDataset[49m[43m([49m[43mroot[49m[43m,[49m[43m [49m[43mcolor_transforms_[49m[38;5;241;43m=[39;49m[43mcolor_transforms_[49m[43m,[49m[43m [49m[43mgray_transforms_[49m[38;5;241;43m=[39;49m[43mgray_transforms_[49m[43m)[49m[43m,[49m
[0;32m      3[0m [43m    [49m[43mbatch_size[49m[38;5;241;43m=[39;49m[43mbatch_size[49m[43m,[49m
[0;32m      4[0m [43m    [49m[43mshuffle[49m[38;5;241;43m=[39;49m[38;5;28;43;01mTrue[39;49;00m
[0;32m      5[0m [43m)[49m

File [1;32mD:\Program Files\Python39\lib\site-packages\torch\utils\data\dataloader.py:376[0m, in [0;36mDataLoader.__init__[1;34m(self, dataset, batch_size, shuffle, sampler, batch_sampler, num_workers, collate_fn, pin_memory, drop_last, timeout, worker_init_fn, multiprocessing_context, generator, prefetch_factor, persistent_workers, pin_memory_device)[0m
[0;32m    374[0m [38;5;28;01melse[39;00m:  [38;5;66;03m# map-style[39;00m
[0;32m    375[0m     [38;5;28;01mif[39;00m shuffle:
[1;32m--> 376[0m         sampler [38;5;241m=[39m [43mRandomSampler[49m[43m([49m[43mdataset[49m[43m,[49m[43m [49m[43mgenerator[49m[38;5;241;43m=[39;49m[43mgenerator[49m[43m)[49m  [38;5;66;03m# type: ignore[arg-type][39;00m
[0;32m    377[0m     [38;5;28;01melse[39;00m:
[0;32m    378[0m         sampler [38;5;241m=[39m SequentialSampler(dataset)  [38;5;66;03m# type: ignore[arg-type][39;00m

File [1;32mD:\Program Files\Python39\lib\site-packages\torch\utils\data\sampler.py:164[0m, in [0;36mRandomSampler.__init__[1;34m(self, data_source, replacement, num_samples, generator)[0m
[0;32m    159[0m     [38;5;28;01mraise[39;00m [38;5;167;01mTypeError[39;00m(
[0;32m    160[0m         [38;5;124mf[39m[38;5;124m"[39m[38;5;124mreplacement should be a boolean value, but got replacement=[39m[38;5;132;01m{[39;00m[38;5;28mself[39m[38;5;241m.[39mreplacement[38;5;132;01m}[39;00m[38;5;124m"[39m
[0;32m    161[0m     )
[0;32m    163[0m [38;5;28;01mif[39;00m [38;5;129;01mnot[39;00m [38;5;28misinstance[39m([38;5;28mself[39m[38;5;241m.[39mnum_samples, [38;5;28mint[39m) [38;5;129;01mor[39;00m [38;5;28mself[39m[38;5;241m.[39mnum_samples [38;5;241m<[39m[38;5;241m=[39m [38;5;241m0[39m:
[1;32m--> 164[0m     [38;5;28;01mraise[39;00m [38;5;167;01mValueError[39;00m(
[0;32m    165[0m         [38;5;124mf[39m[38;5;124m"[39m[38;5;124mnum_samples should be a positive integer value, but got num_samples=[39m[38;5;132;01m{[39;00m[38;5;28mself[39m[38;5;241m.[39mnum_samples[38;5;132;01m}[39;00m[38;5;124m"[39m
[0;32m    166[0m     )

[1;31mValueError[0m: num_samples should be a positive integer value, but got num_samples=0

