Traceback (most recent call last):
  File "D:\Program Files\Python39\lib\site-packages\jupyter_cache\executors\utils.py", line 58, in single_nb_execution
    executenb(
  File "D:\Program Files\Python39\lib\site-packages\nbclient\client.py", line 1314, in execute
    return NotebookClient(nb=nb, resources=resources, km=km, **kwargs).execute()
  File "D:\Program Files\Python39\lib\site-packages\jupyter_core\utils\__init__.py", line 165, in wrapped
    return loop.run_until_complete(inner)
  File "D:\Program Files\Python39\lib\asyncio\base_events.py", line 642, in run_until_complete
    return future.result()
  File "D:\Program Files\Python39\lib\site-packages\nbclient\client.py", line 709, in async_execute
    await self.async_execute_cell(
  File "D:\Program Files\Python39\lib\site-packages\nbclient\client.py", line 1062, in async_execute_cell
    await self._check_raise_for_error(cell, cell_index, exec_reply)
  File "D:\Program Files\Python39\lib\site-packages\nbclient\client.py", line 918, in _check_raise_for_error
    raise CellExecutionError.from_cell_and_msg(cell, exec_reply_content)
nbclient.exceptions.CellExecutionError: An error occurred while executing the following cell:
------------------
import pickle
file_name = "CoNLL+BEA_corrected_essays.pkl"
open_file = open(file_name, "rb")
data = pickle.load(open_file)
open_file.close()
------------------


[1;31m---------------------------------------------------------------------------[0m
[1;31mFileNotFoundError[0m                         Traceback (most recent call last)
Cell [1;32mIn[2], line 3[0m
[0;32m      1[0m [38;5;28;01mimport[39;00m [38;5;21;01mpickle[39;00m
[0;32m      2[0m file_name [38;5;241m=[39m [38;5;124m"[39m[38;5;124mCoNLL+BEA_corrected_essays.pkl[39m[38;5;124m"[39m
[1;32m----> 3[0m open_file [38;5;241m=[39m [38;5;28;43mopen[39;49m[43m([49m[43mfile_name[49m[43m,[49m[43m [49m[38;5;124;43m"[39;49m[38;5;124;43mrb[39;49m[38;5;124;43m"[39;49m[43m)[49m
[0;32m      4[0m data [38;5;241m=[39m pickle[38;5;241m.[39mload(open_file)
[0;32m      5[0m open_file[38;5;241m.[39mclose()

File [1;32mD:\Program Files\Python39\lib\site-packages\IPython\core\interactiveshell.py:310[0m, in [0;36m_modified_open[1;34m(file, *args, **kwargs)[0m
[0;32m    303[0m [38;5;28;01mif[39;00m file [38;5;129;01min[39;00m {[38;5;241m0[39m, [38;5;241m1[39m, [38;5;241m2[39m}:
[0;32m    304[0m     [38;5;28;01mraise[39;00m [38;5;167;01mValueError[39;00m(
[0;32m    305[0m         [38;5;124mf[39m[38;5;124m"[39m[38;5;124mIPython won[39m[38;5;124m'[39m[38;5;124mt let you open fd=[39m[38;5;132;01m{[39;00mfile[38;5;132;01m}[39;00m[38;5;124m by default [39m[38;5;124m"[39m
[0;32m    306[0m         [38;5;124m"[39m[38;5;124mas it is likely to crash IPython. If you know what you are doing, [39m[38;5;124m"[39m
[0;32m    307[0m         [38;5;124m"[39m[38;5;124myou can use builtins[39m[38;5;124m'[39m[38;5;124m open.[39m[38;5;124m"[39m
[0;32m    308[0m     )
[1;32m--> 310[0m [38;5;28;01mreturn[39;00m io_open(file, [38;5;241m*[39margs, [38;5;241m*[39m[38;5;241m*[39mkwargs)

[1;31mFileNotFoundError[0m: [Errno 2] No such file or directory: 'CoNLL+BEA_corrected_essays.pkl'

